Workbook

Sheet Three Statement Model
B1: Historical | G1: Forecast
B2: 2020 | C2: 2021 | D2: 2022 | E2: 2023 | F2: 2024 | G2: 2025 | H2: 2026 | I2: 2027 | J2: 2028 | K2: 2029
A3: =IF(L32=0,"OK","NOT BALANCED") -> OK | B3: -5 | C3: -4 | D3: -3 | E3: -2 | F3: -1 | G3: 1 | H3: =G3+1 -> 2 | I3: =H3+1 -> 3 | J3: =I3+1 -> 4 | K3: =J3+1 -> 5
A4: ($ in millions) | F4: CASE: | G4: 2 | H4: =CHOOSE(G4,"BEAR","BASE","BULL") -> BASE
A5: BALANCE SHEET
A6: Assets
A7: Cash and Cash Equivalents | B7: 19384 | C7: 17576 | D7: 16253 | E7: 16398 | F7: 16139 | G7: =G132 -> 18196.17 | H7: =H132 -> 20124.579 | I7: =I132 -> 22210.089 | J7: =J132 -> 24097.233 | K7: =K132 -> 25986.212
A8: EXCESS CASH | G8: =IF(G92>0,G92,0) -> 0 | H8: =IF(H92>0,H92,0) -> 0 | I8: =IF(I92>0,I92,0) -> 0 | J8: =IF(J92>0,J92,0) -> 0 | K8: =IF(K92>0,K92,0) -> 0
A9: Short-term Investments | B9: 0 | C9: 131 | D9: 5932 | E9: 12696 | F9: 20424 | G9: =G133 -> 16055.444 | H9: =H133 -> 17756.981 | I9: =I133 -> 19597.137 | J9: =J133 -> 21262.264 | K9: =K133 -> 22929.011
A10: Accounts Receivable, net | B10: 1886 | C10: 1913 | D10: 2952 | E10: 3508 | F10: 4418 | G10: =G134 -> 4388.4881 | H10: =H134 -> 4853.5748 | I10: =I134 -> 5356.5508 | J10: =J134 -> 5811.6855 | K10: =K134 -> 6267.2629
A11: Inventory | B11: 4101 | C11: 5757 | D11: 12839 | E11: 13626 | F11: 12017 | G11: =G135 -> 16186.521 | H11: =H135 -> 17752.967 | I11: =I135 -> 19172.289 | J11: =J135 -> 20410.623 | K11: =K135 -> 21646.359
A12: Prepaid Expenses | B12: 1346 | C12: 1723 | D12: 2941 | E12: 3388 | F12: 5362 | G12: =G136 -> 4281.4518 | H12: =H136 -> 4735.195 | I12: =I136 -> 5225.9032 | J12: =J136 -> 5669.9371 | K12: =K136 -> 6114.4028
A13: PP&E, net | B13: 12747 | C13: 18884 | D13: 23548 | E13: 29725 | F13: 35836 | G13: =G37 -> 40652.633 | H13: =H37 -> 45979.728 | I13: =I37 -> 51858.869 | J13: =J37 -> 58237.548 | K13: =K37 -> 65116.251
A14: Goodwill | B14: 207 | C14: 200 | D14: 194 | E14: 253 | F14: 244 | G14: 244 | H14: 244 | I14: 244 | J14: 244 | K14: 244
A15: Other Assets | B15: 12477 | C15: 15947 | D15: 17679 | E15: 27024 | F15: 27630 | G15: =F15 -> 27630 | H15: =G15 -> 27630 | I15: =H15 -> 27630 | J15: =I15 -> 27630 | K15: =J15 -> 27630
A16: Total Assets | B16: 52148 | C16: 62131 | D16: 82338 | E16: 106618 | F16: 122070 | G16: =SUM(G7:G15) -> 127634.71 | H16: =SUM(H7:H15) -> 139077.02 | I16: =SUM(I7:I15) -> 151294.84 | J16: =SUM(J7:J15) -> 163363.29 | K16: =SUM(K7:K15) -> 175933.5
A18: Liabilities
A19: A/P & Accrued Liabilities | B19: 10658 | C19: 16669 | D19: 23460 | E19: 23511 | F19: 23197 | G19: =G138 -> 27123.36 | H19: =H138 -> 29748.215 | I19: =I138 -> 32126.539 | J19: =J138 -> 34201.584 | K19: =K138 -> 36272.277
A20: Deferred Revenue | B20: 1458 | C20: 1447 | D20: 1747 | E20: 2864 | F20: 3168 | G20: =G139 -> 3211.0889 | H20: =H139 -> 3551.3962 | I20: =I139 -> 3919.4274 | J20: =J139 -> 4252.4528 | K20: =K139 -> 4585.8021
A21: NEW Revolver | G21: =-IF(G92<0,G92,0) -> 349.67602 | H21: =-IF(H92<0,H92,0) -> 6959.2964 | I21: =-IF(I92<0,I92,0) -> 8667.4409 | J21: =-IF(J92<0,J92,0) -> 7829.3779 | K21: =-IF(K92<0,K92,0) -> 4923.6753
A22: Debt | B22: 11739 | C22: 6834 | D22: 3099 | E22: 5230 | F22: 8213 | G22: =G142 -> 5860 | H22: =H142 -> 1744 | I22: =I142 -> 1045 | J22: =J142 -> 802 | K22: =K142 -> 707
A23: Other Liabilities | B23: 4614 | C23: 5598 | D23: 8134 | E23: 11404 | F23: 13812 | G23: =G140 -> 13979.271 | H23: =H140 -> 15352.06 | I23: =I140 -> 16636.203 | J23: =J140 -> 17764.644 | K23: =K140 -> 18891.408
A24: Total Liabilities | B24: =SUM(B19:B23) -> 28469 | C24: =SUM(C19:C23) -> 30548 | D24: =SUM(D19:D23) -> 36440 | E24: =SUM(E19:E23) -> 43009 | F24: =SUM(F19:F23) -> 48390 | G24: =SUM(G19:G23) -> 50523.395 | H24: =SUM(H19:H23) -> 57354.968 | I24: =SUM(I19:I23) -> 62394.61 | ... K24: =SUM(K19:K23) -> 65380.163
A25: Shareholder's Equity
A26: Paid-in Capital | B26: 27261 | C26: 29804 | D26: 32180 | E26: 34895 | F26: 38374 | G26: =F26 -> 38374 | H26: =G26 -> 38374 | I26: =H26 -> 38374 | J26: =I26 -> 38374 | K26: =J26 -> 38374
A27: Other Equity | B27: 363 | C27: 54 | D27: -361 | E27: -143 | F27: -670 | G27: =F27 -> -670 | H27: =G27 -> -670 | I27: =H27 -> -670 | J27: =I27 -> -670 | K27: =J27 -> -670
A28: Retained Earnings | B28: -5399 | C28: 331 | D28: 12885 | E28: 27882 | F28: 35209 | G28: =G59 -> 38640.313 | H28: =H59 -> 43251.056 | I28: =I59 -> 50429.228 | J28: =J59 -> 60042.231 | K28: =K59 -> 72082.335
A29: Noncontrolling Interests | B29: 1454 | C29: 1394 | D29: 1194 | E29: 975 | F29: 767 | G29: =F29 -> 767 | H29: =G29 -> 767 | I29: =H29 -> 767 | J29: =I29 -> 767 | K29: =J29 -> 767
A30: Shareholder's Equity | B30: =SUM(B26:B29) -> 23679 | C30: =SUM(C26:C29) -> 31583 | D30: =SUM(D26:D29) -> 45898 | E30: =SUM(E26:E29) -> 63609 | F30: =SUM(F26:F29) -> 73680 | G30: =SUM(G26:G29) -> 77111.313 | H30: =SUM(H26:H29) -> 81722.056 | I30: =SUM(I26:I29) -> 88900.228 | ... K30: =SUM(K26:K29) -> 110553.34
A31: Total Liabilities and Shareholder's Equity | B31: =B24+B30 -> 52148 | C31: =C24+C30 -> 62131 | D31: =D24+D30 -> 82338 | E31: =E24+E30 -> 106618 | F31: =F24+F30 -> 122070 | G31: =G24+G30 -> 127634.71 | H31: =H24+H30 -> 139077.02 | I31: =I24+I30 -> 151294.84 | ... K31: =K24+K30 -> 175933.5
A32: Check | B32: 0 | C32: 0 | D32: 0 | E32: 0 | F32: 0 | H32: =H16-H31 -> 0 | I32: =I16-I31 -> 0 | J32: =J16-J31 -> 0 | K32: =K16-K31 -> 0 | L32: =SUM(B32:K32) -> 0
A34: Beginning PP&E | G34: =F37 -> 35836 | H34: =G37 -> 40652.633 | I34: =H37 -> 45979.728 | J34: =I37 -> 51858.869 | K34: =J37 -> 58237.548
A35: + Capex | G35: =+G143 -> 10703.63 | H35: =+H143 -> 11837.987 | I35: =+I143 -> 13064.758 | J35: =+J143 -> 14174.843 | K35: =+K143 -> 15286.007
A36: - D&A | G36: =G126 -> 5886.9962 | H36: =H126 -> 6510.8931 | I36: =I126 -> 7185.6169 | J36: =J126 -> 7796.1635 | K36: =K126 -> 8407.3039
A37: Ending PP&E | F37: =F13 -> 35836 | G37: =G34+G35-G36 -> 40652.633 | H37: =H34+H35-H36 -> 45979.728 | I37: =I34+I35-I36 -> 51858.869 | J37: =J34+J35-J36 -> 58237.548 | K37: =K34+K35-K36 -> 65116.251
A39: INCOME STATEMENT
A40: Revenues | B40: 31536 | C40: 53823 | D40: 81462 | E40: 96773 | F40: 97690 | G40: =G124 -> 107036.3 | H40: =H124 -> 118379.87 | I40: =I124 -> 130647.58 | J40: =J124 -> 141748.43 | K40: =K124 -> 152860.07
A41: Cost of Goods Sold | B41: 22584 | C41: 37306 | D41: 56862 | E41: 74446 | F41: 74872 | G41: =G125 -> 87494.709 | H41: =H125 -> 95961.984 | I41: =I125 -> 103634 | J41: =J125 -> 110327.69 | K41: =K125 -> 117007.35
A42: Gross profit | B42: 8952 | C42: 16517 | D42: 24600 | E42: 22327 | F42: 22818 | G42: =G40-G41 -> 19541.586 | H42: =H40-H41 -> 22417.891 | I42: =I40-I41 -> 27013.584 | J42: =J40-J41 -> 31420.735 | K42: =K40-K41 -> 35852.724
A43: R&D | B43: 1491 | C43: 2593 | D43: 3075 | E43: 3969 | F43: 4540 | G43: =G127 -> 4816.6333 | H43: =H127 -> 5327.0943 | I43: =I127 -> 5879.1411 | J43: =J127 -> 6378.6792 | K43: =K127 -> 6878.7032
...

Sheet Charts and Graphs
A1: CHART AND GRAPHS | B1: Historical | G1: Forecast
A2: ($ in millions) | B2: 44196 | C2: 44561 | D2: 44926 | E2: 45291 | F2: 45657 | G2: 46022 | H2: 46387 | I2: 46752 | J2: 47118 | K2: 47483
A4: Revenue | B4: ='Three Statement Model'!B40 -> 31536 | C4: ='Three Statement Model'!C40 -> 53823 | D4: ='Three Statement Model'!D40 -> 81462 | E4: ='Three Statement Model'!E40 -> 96773 | F4: ='Three Statement Model'!F40 -> 97690 | G4: ='Three Statement Model'!G40 -> 107036.3 | H4: ='Three Statement Model'!H40 -> 118379.87 | I4: ='Three Statement Model'!I40 -> 130647.58 | ... K4: ='Three Statement Model'!K40 -> 152860.07
A5: Gross Profit Margin (%) | B5: ='Three Statement Model'!B42/'Three Statement Model'!B40 -> 0.28386606 | C5: ='Three Statement Model'!C42/'Three Statement Model'!C40 -> 0.30687624 | D5: ='Three Statement Model'!D42/'Three Statement Model'!D40 -> 0.30198129 | E5: ='Three Statement Model'!E42/'Three Statement Model'!E40 -> 0.23071518 | F5: ='Three Statement Model'!F42/'Three Statement Model'!F40 -> 0.2335756 | G5: ='Three Statement Model'!G42/'Three Statement Model'!G40 -> 0.18256972 | H5: ='Three Statement Model'!H42/'Three Statement Model'!H40 -> 0.18937248 | I5: ='Three Statement Model'!I42/'Three Statement Model'!I40 -> 0.20676682 | ... K5: ='Three Statement Model'!K42/'Three Statement Model'!K40 -> 0.23454604
A7: Operating Cash Flow | B7: ='Three Statement Model'!B71 -> 5943 | C7: ='Three Statement Model'!C71 -> 11497 | D7: ='Three Statement Model'!D71 -> 14724 | E7: ='Three Statement Model'!E71 -> 13256 | F7: ='Three Statement Model'!F71 -> 14923 | G7: ='Three Statement Model'!G71 -> 10395.568 | H7: ='Three Statement Model'!H71 -> 12974.312 | I7: ='Three Statement Model'!I71 -> 15981.279 | ... K7: ='Three Statement Model'!K71 -> 21842.435
A8: Investing Cash Flow | B8: ='Three Statement Model'!B76 -> -3132 | C8: ='Three Statement Model'!C76 -> -7868 | D8: ='Three Statement Model'!D76 -> -11973 | E8: ='Three Statement Model'!E76 -> -15584 | F8: ='Three Statement Model'!F76 -> -18787 | G8: ='Three Statement Model'!G76 -> -6335.0738 | H8: ='Three Statement Model'!H76 -> -13539.524 | I8: ='Three Statement Model'!I76 -> -14904.914 | ... K8: ='Three Statement Model'!K76 -> -16952.754
A9: Financing Cash Flow | B9: ='Three Statement Model'!B83 -> 9973 | C9: ='Three Statement Model'!C83 -> -5203 | D9: ='Three Statement Model'!D83 -> -3527 | E9: ='Three Statement Model'!E83 -> 2589 | F9: ='Three Statement Model'!F83 -> 3853 | G9: ='Three Statement Model'!G83 -> -2353 | H9: ='Three Statement Model'!H83 -> -4116 | I9: ='Three Statement Model'!I83 -> -699 | ... K9: ='Three Statement Model'!K83 -> -95

Sheet Rev&COGS breakdown
A1: REVENUE&COGS BREAKDOWN
A2: INCOME STATEMENT
A3: Automotive | B3: 27236 | C3: 47232 | D3: 71462 | E3: 82419 | F3: 77070 | G3: =G15*G17 -> 79266.495 | H3: =H15*H17 -> 83039.58 | I3: =I15*I17 -> 87963.827 | J3: =J15*J17 -> 91900.209 | K3: =K15*K17 -> 96495.219
A4: Energy Generation and Storage | B4: 1994 | C4: 2789 | D4: 3909 | E4: 6035 | F4: 10086 | G4: =F4*(1+G23) -> 15129 | H4: =G4*(1+H23) -> 20424.15 | I4: =H4*(1+I23) -> 25530.188 | J4: =I4*(1+J23) -> 30636.225 | K4: =J4*(1+K23) -> 35231.659
A5: Services and Other | B5: 2306 | C5: 3802 | D5: 6091 | E5: 8319 | F5: 10534 | G5: =F5*(1+G27) -> 12640.8 | H5: =G5*(1+H27) -> 14916.144 | I5: =H5*(1+I27) -> 17153.566 | J5: =I5*(1+J27) -> 19211.993 | K5: =J5*(1+K27) -> 21133.193
A6: Total Revenue | B6: =SUM(B3:B5) -> 31536 | C6: =SUM(C3:C5) -> 53823 | D6: =SUM(D3:D5) -> 81462 | E6: =SUM(E3:E5) -> 96773 | F6: =SUM(F3:F5) -> 97690 | G6: =SUM(G3:G5) -> 107036.3 | H6: =SUM(H3:H5) -> 118379.87 | I6: =SUM(I3:I5) -> 130647.58 | ... K6: =SUM(K3:K5) -> 152860.07
A8: Cost of Automotive | B8: 20259 | C8: 33393 | D8: 51108 | E8: 66389 | F8: 62873 | G8: =G15*G19 -> 67500.453 | H8: =H15*H19 -> 71223.778 | I8: =I15*I19 -> 74609.044 | J8: =J15*J19 -> 76929.385 | K8: =K15*K19 -> 79806.544
A9: Cost of Energy Generation and Storage | B9: 1976 | C9: 2918 | D9: 3621 | E9: 4894 | F9: 7446 | G9: =G4*(1-G24) -> 10892.88 | H9: =H4*(1-H24) -> 14296.905 | I9: =I4*(1-I24) -> 17360.528 | J9: =J4*(1-J24) -> 20526.271 | K9: =K4*(1-K24) -> 23252.895
A10: Cost of Services and Other | B10: 2671 | C10: 3906 | D10: 5880 | E10: 7830 | F10: 9921 | G10: =G5*(1-G24) -> 9101.376 | H10: =H5*(1-H24) -> 10441.301 | I10: =I5*(1-I24) -> 11664.425 | J10: =J5*(1-J24) -> 12872.036 | K10: =K5*(1-K24) -> 13947.907
A11: Cost of Goods Sold (COGS) | B11: =SUM(B8:B10) -> 24906 | C11: =SUM(C8:C10) -> 40217 | D11: =SUM(D8:D10) -> 60609 | E11: =SUM(E8:E10) -> 79113 | F11: =SUM(F8:F10) -> 80240 | G11: =SUM(G8:G10) -> 87494.709 | H11: =SUM(H8:H10) -> 95961.984 | I11: =SUM(I8:I10) -> 103634 | ... K11: =SUM(K8:K10) -> 117007.35
A13: DRIVERS
A14: Automotive
A15: Vehicle Deliveries | B15: 499647 | C15: 936222 | D15: 1313851 | E15: 1808581 | F15: 1789266 | G15: =F15*(1+G16) -> 1968192.6 | H15: =G15*(1+H16) -> 2125648 | I15: =H15*(1+I16) -> 2274443.4 | J15: =I15*(1+J16) -> 2388165.5 | K15: =J15*(1+K16) -> 2507573.8
A16: Delivery Growth % | C16: =C15/B15-1 -> 0.87376688 | D16: =D15/C15-1 -> 0.40335412 | E16: =E15/D15-1 -> 0.37654955 | F16: =F15/E15-1 -> -0.010679643 | G16: 0.1 | H16: 0.08 | I16: 0.07 | J16: 0.05 | K16: 0.05
A17: Average Selling Price ($M) | B17: =B3/B15 -> 0.054510484 | C17: =C3/C15 -> 0.050449573 | D17: =D3/D15 -> 0.054391251 | E17: =E3/E15 -> 0.045571086 | F17: =F3/F15 -> 0.043073528 | G17: =F17*(1+G18) -> 0.040273749 | H17: =G17*(1+H18) -> 0.039065537 | I17: =H17*(1+I18) -> 0.038674881 | J17: =I17*(1+J18) -> 0.038481507 | K17: =J17*(1+K18) -> 0.038481507
A18: ASP Change % | C18: =C17/B17-1 -> -0.074497807 | D18: =D17/C17-1 -> 0.078131058 | E18: =E17/D17-1 -> -0.16216147 | F18: =F17/E17-1 -> -0.054805746 | G18: -0.065 | H18: -0.03 | I18: -0.01 | J18: -0.005 | K18: 0
A19: Average Cost per Vehicle ($M) | B19: =B8/B15 -> 0.040546626 | C19: =C8/C15 -> 0.035667822 | D19: =D8/D15 -> 0.038899388 | E19: =E8/E15 -> 0.036707784 | F19: =F8/F15 -> 0.03513899 | G19: =F19*(1+G20) -> 0.034295654 | H19: =G19*(1+H20) -> 0.033506854 | I19: =H19*(1+I20) -> 0.03280321 | J19: =I19*(1+J20) -> 0.032212752 | K19: =J19*(1+K20) -> 0.031826199
A20: Cost Change % | C20: =C19/B19-1 -> -0.12032576 | D20: =D19/C19-1 -> 0.090601712 | E20: =E19/D19-1 -> -0.056340334 | F20: =F19/E19-1 -> -0.042737357 | G20: -0.024 | H20: -0.023 | I20: -0.021 | J20: -0.018 | K20: -0.012
A22: Energy Generation and Storage
A23: Energy Revenue Growth % | C23: =C4/B4-1 -> 0.39869609 | D23: =D4/C4-1 -> 0.40157763 | E23: =E4/D4-1 -> 0.54387311 | F23: =F4/E4-1 -> 0.67125104 | G23: 0.5 | H23: 0.35 | I23: 0.25 | J23: 0.2 | K23: 0.15
A24: Energy Gross Margin | B24: =1-B9/B4 -> 0.0090270812 | C24: =1-C9/C4 -> -0.046253137 | D24: =1-D9/D4 -> 0.073676132 | E24: =1-E9/E4 -> 0.18906379 | F24: =1-F9/F4 -> 0.26174896 | G24: 0.28 | H24: 0.3 | I24: 0.32 | J24: 0.33 | K24: 0.34
A26: Services and Other
A27: Services and Other Growth % | C27: =C5/B5-1 -> 0.64874241 | D27: =D5/C5-1 -> 0.60205155 | E27: =E5/D5-1 -> 0.36578559 | F27: =F5/E5-1 -> 0.26625796 | G27: 0.2 | H27: 0.18 | I27: 0.15 | J27: 0.12 | K27: 0.1
A28: Services Gross Margin | B28: =1-B10/B5 -> -0.15828274 | C28: =1-C10/C5 -> -0.027354024 | D28: =1-D10/D5 -> 0.034641274 | E28: =1-E10/E5 -> 0.058781103 | F28: =1-F10/F5 -> 0.058192519 | G28: 0.06 | H28: 0.065 | I28: 0.065 | J28: 0.07 | K28: 0.07

Sheet Financials
B1: 2020 | C1: 2021 | D1: 2022 | E1: 2023 | F1: 2024
A2: BALANCE SHEET
A3: Assets | G3: BUCKET | J3: 2020 | K3: 2021 | L3: 2022 | M3: 2023 | N3: 2024
A4: Cash and cash equivalents | B4: 19384 | C4: 17576 | D4: 16253 | E4: 16398 | F4: 16139 | G4: Cash and cash equivalents | I4: Cash and cash equivalents | J4: =B4 -> 19384 | K4: =C4 -> 17576 | L4: =D4 -> 16253 | M4: =E4 -> 16398 | N4: =F4 -> 16139
A5: Short-term investments | B5: 0 | C5: 131 | D5: 5932 | E5: 12696 | F5: 20424 | G5: Short-term investments | I5: Short-term investments | J5: =B5 -> 0 | K5: =C5 -> 131 | L5: =D5 -> 5932 | M5: =E5 -> 12696 | N5: =F5 -> 20424
A6: Accounts receivable, net | B6: 1886 | C6: 1913 | D6: 2952 | E6: 3508 | F6: 4418 | G6: Accounts receivable, net | I6: Accounts receivable, net | J6: =B6 -> 1886 | K6: =C6 -> 1913 | L6: =D6 -> 2952 | M6: =E6 -> 3508 | N6: =F6 -> 4418
A7: Inventory | B7: 4101 | C7: 5757 | D7: 12839 | E7: 13626 | F7: 12017 | G7: Inventory | I7: Inventory | J7: =B7 -> 4101 | K7: =C7 -> 5757 | L7: =D7 -> 12839 | M7: =E7 -> 13626 | N7: =F7 -> 12017
A8: Prepaid expenses and other current assets | B8: 1346 | C8: 1723 | D8: 2941 | E8: 3388 | F8: 5362 | G8: Prepaid expenses | I8: Prepaid expenses | J8: =B8 -> 1346 | K8: =C8 -> 1723 | L8: =D8 -> 2941 | M8: =E8 -> 3388 | N8: =F8 -> 5362
A9: Total current assets | B9: 26717 | C9: 27100 | D9: =SUM(D4:D8) -> 40917 | E9: 49616 | F9: 58360 | I9: PP&E, net | J9: =B12 -> 12747 | K9: =C12 -> 18884 | L9: =D12 -> 23548 | M9: =E12 -> 29725 | N9: =F12 -> 35836
A10: Operating lease vehicles, net | B10: 3091 | C10: 4511 | D10: 5035 | E10: 5989 | F10: 5581 | G10: Other assets | I10: Goodwill | J10: =B16 -> 207 | K10: =C16 -> 200 | L10: =D16 -> 194 | M10: =E16 -> 253 | N10: =F16 -> 244
A11: Solar energy systems, net | B11: 5979 | C11: 5765 | D11: 5489 | E11: 5229 | F11: 4924 | G11: Other assets | I11: Other assets | J11: =B10+B11+B13+B14+B15+B17+B18 -> 12477 | K11: =C10+C11+C13+C14+C15+C17+C18 -> 15947 | L11: =D10+D11+D13+D14+D15+D17+D18 -> 17679 | M11: =E10+E11+E13+E14+E15+E17+E18 -> 27024 | N11: =F10+F11+F13+F14+F15+F17+F18 -> 27630
A12: Property, plant and equipment, net | B12: 12747 | C12: 18884 | D12: 23548 | E12: 29725 | F12: 35836 | G12: PP&E, net | I12: Total assets | J12: =SUM(J4:J11) -> 52148 | K12: =SUM(K4:K11) -> 62131 | L12: =SUM(L4:L11) -> 82338 | M12: =SUM(M4:M11) -> 106618 | N12: =SUM(N4:N11) -> 122070
A13: Operating lease right-of-use assets | B13: 1558 | C13: 2016 | D13: 2563 | E13: 4180 | F13: 5160 | G13: Other assets | I13: A/P & Accrued Liabilities | J13: =B22+B23 -> 10658 | K13: =C22+C23 -> 16669 | L13: =D22+D23 -> 23460 | M13: =E22+E23 -> 23511 | N13: =F22+F23 -> 23197
A14: Digital assets, net | B14: 0 | C14: 1260 | D14: 184 | E14: 184 | F14: 1076 | G14: Other assets | I14: Deferred revenue | J14: =B24 -> 1458 | K14: =C24 -> 1447 | L14: =D24 -> 1747 | M14: =E24 -> 2864 | N14: =F24 -> 3168
A15: Intangible assets, net | B15: 313 | C15: 257 | D15: 215 | E15: 178 | F15: 150 | G15: Other assets | I15: Debt | J15: =B25+B27+B33 -> 11739 | K15: =C25+C27+C33 -> 6834 | L15: =D25+D27+D33 -> 3099 | M15: =E25+E27+E33 -> 5230 | N15: =F25+F27+F33 -> 8213
A16: Goodwill | B16: 207 | C16: 200 | D16: 194 | E16: 253 | F16: 244 | G16: Goodwill | I16: Other liabilities | J16: =B28+B29 -> 4614 | K16: =C28+C29 -> 5598 | L16: =D28+D29 -> 8134 | M16: =E28+E29 -> 11404 | N16: =F28+F29 -> 13812
A17: Deferred tax assets | B17: 0 | C17: 0 | D17: 0 | E17: 6733 | F17: 6524 | G17: Other assets | I17: Paid in capital | J17: =B37+B38 -> 27261 | K17: =C37+C38 -> 29804 | L17: =D37+D38 -> 32180 | M17: =E37+E38 -> 34895 | N17: =F37+F38 -> 38374
A18: Other non-current assets | B18: 1536 | C18: 2138 | D18: 4193 | E18: 4531 | F18: 4215 | G18: Other assets | I18: Other equity | J18: =B39 -> 363 | K18: =C39 -> 54 | L18: =D39 -> -361 | M18: =E39 -> -143 | N18: =F39 -> -670
A19: Total assets | B19: 52148 | C19: 62131 | D19: 82338 | E19: 106618 | F19: 122070 | I19: Retained earnings | J19: =B40 -> -5399 | K19: =C40 -> 331 | L19: =D40 -> 12885 | M19: =E40 -> 27882 | N19: =F40 -> 35209
I20: Noncontrolling interests | J20: =B32+B42 -> 1454 | K20: =C32+C42 -> 1394 | L20: =D32+D42 -> 1194 | M20: =E32+E42 -> 975 | N20: =F32+F42 -> 767
A21: Liabilities | I21: Total liabilities and equity | J21: =SUM(J13:J20) -> 52148 | K21: =SUM(K13:K20) -> 62131 | L21: =SUM(L13:L20) -> 82338 | M21: =SUM(M13:M20) -> 106618 | N21: =SUM(N13:N20) -> 122070
A22: Accounts payable | B22: 6051 | C22: 10025 | D22: 15255 | E22: 14431 | F22: 12474 | G22: A/P & Accrued Liabilities | I22: Check | J22: =J12-J21 -> 0 | K22: =K12-K21 -> 0 | L22: =L12-L21 -> 0 | M22: =M12-M21 -> 0 | N22: =N12-N21 -> 0
A23: Accrued liabilities and other | B23: =3855+752 -> 4607 | C23: =5719+925 -> 6644 | D23: =7142+1063 -> 8205 | E23: 9080 | F23: 10723 | G23: A/P & Accrued Liabilities
A24: Deferred revenue | B24: 1458 | C24: 1447 | D24: 1747 | E24: 2864 | F24: 3168 | G24: Deferred revenue
A25: Current portion of debt and finance leases | B25: 2132 | C25: 1589 | D25: 1502 | E25: 2373 | F25: 2456 | G25: Debt
A26: Total current liabilities | B26: 14248 | C26: 19705 | D26: =SUM(D22:D25) -> 26709 | E26: 28748 | F26: 28821
A27: Debt and finance leases, net of current portion | B27: 9556 | C27: 5245 | D27: 1597 | E27: 2857 | F27: 5757 | G27: Debt
A28: Deferred revenue, net of current portion | B28: 1284 | C28: 2052 | D28: 2804 | E28: 3251 | F28: 3317 | G28: Other liabilities
A29: Other long-term liabilities | B29: 3330 | C29: 3546 | D29: 5330 | E29: 8153 | F29: 10495 | G29: Other liabilities
A30: Total liabilities | B30: 28418 | C30: 30548 | D30: 36440 | E30: 43009 | F30: 48390
A32: Redeemable noncontrolling interests in subsidiaries | B32: 604 | C32: 568 | D32: 409 | E32: 242 | F32: 63 | G32: Noncontrolling interests
A33: Convertible senior notes | B33: 51 | C33: 0 | D33: 0 | E33: 0 | F33: 0 | G33: Debt
A35: Equity
A36: Preferred stock | B36: 0 | C36: 0 | D36: 0 | E36: 0 | F36: 0
A37: Common stock | B37: 1 | C37: 1 | D37: 3 | E37: 3 | F37: 3 | G37: Paid in capital
A38: Additional paid-in capital | B38: 27260 | C38: 29803 | D38: 32177 | E38: 34892 | F38: 38371 | G38: Paid in capital
A39: Accumulated other comprehensive loss | B39: 363 | C39: 54 | D39: -361 | E39: -143 | F39: -670 | G39: Other equity
A40: Retained earnings | B40: -5399 | C40: 331 | D40: 12885 | E40: 27882 | F40: 35209 | G40: Retained earnings
A41: Total stockholders’ equity | B41: 22225 | C41: 30189 | D41: 44705 | E41: 62634 | F41: 72913
A42: Noncontrolling interests in subsidiaries | B42: 850 | C42: 826 | D42: 785 | E42: 733 | F42: 704 | G42: Noncontrolling interests
...

Sheet 3-Statement Model_v1
B1: Historical | G1: Forecast
B2: 2020 | C2: 2021 | D2: 2022 | E2: 2023 | F2: 2024 | G2: 2025 | H2: 2026 | I2: 2027 | J2: 2028 | K2: 2029
A3: =IF(L32=0,"OK","NOT BALANCED") -> OK | B3: -5 | C3: -4 | D3: -3 | E3: -2 | F3: -1 | G3: 1 | H3: =G3+1 -> 2 | I3: =H3+1 -> 3 | J3: =I3+1 -> 4 | K3: =J3+1 -> 5
A4: ($ in millions) | F4: CASE: | G4: 2 | H4: =CHOOSE(G4,"BEAR","BASE","BULL") -> BASE
A5: BALANCE SHEET
A6: Assets
A7: Cash and Cash Equivalents | B7: 19384 | C7: 17576 | D7: 16253 | E7: 16398 | F7: 16139 | G7: =G103 -> 17105.519 | H7: =H103 -> 17618.685 | I7: =I103 -> 18147.245 | J7: =J103 -> 18691.662 | K7: =K103 -> 19252.412
A8: EXCESS CASH | G8: =IF(G92>0,G92,0) -> 4585.4875 | H8: =IF(H92>0,H92,0) -> 4912.9895 | I8: =IF(I92>0,I92,0) -> 8962.5995 | J8: =IF(J92>0,J92,0) -> 13835.74 | K8: =IF(K92>0,K92,0) -> 19252.789
A9: Short-term Investments | B9: 0 | C9: 131 | D9: 5932 | E9: 12696 | F9: 20424 | G9: =G104 -> 15093.105 | H9: =H104 -> 15545.898 | I9: =I104 -> 16012.275 | J9: =J104 -> 16492.643 | K9: =K104 -> 16987.423
A10: Accounts Receivable, net | B10: 1886 | C10: 1913 | D10: 2952 | E10: 3508 | F10: 4418 | G10: =G105 -> 4125.4487 | H10: =H105 -> 4249.2122 | I10: =I105 -> 4376.6885 | J10: =J105 -> 4507.9892 | K10: =K105 -> 4643.2289
A11: Inventory | B11: 4101 | C11: 5757 | D11: 12839 | E11: 13626 | F11: 12017 | G11: =G106 -> 13961.122 | H11: =H106 -> 14379.956 | I11: =I106 -> 14811.354 | J11: =J106 -> 15255.695 | K11: =K106 -> 15713.366
A12: Prepaid Expenses | B12: 1346 | C12: 1723 | D12: 2941 | E12: 3388 | F12: 5362 | G12: =G107 -> 4024.828 | H12: =H107 -> 4145.5728 | I12: =I107 -> 4269.94 | J12: =J107 -> 4398.0382 | K12: =K107 -> 4529.9794
A13: PP&E, net | B13: 12747 | C13: 18884 | D13: 23548 | E13: 29725 | F13: 35836 | G13: =G37 -> 40363.931 | H13: =H37 -> 45027.701 | I13: =I37 -> 49831.383 | J13: =J37 -> 54779.176 | K13: =K37 -> 59875.403
A14: Goodwill | B14: 207 | C14: 200 | D14: 194 | E14: 253 | F14: 244 | G14: 244 | H14: 244 | I14: 244 | J14: 244 | K14: 244
A15: Other Assets | B15: 12477 | C15: 15947 | D15: 17679 | E15: 27024 | F15: 27630 | G15: =F15 -> 27630 | H15: =G15 -> 27630 | I15: =H15 -> 27630 | J15: =I15 -> 27630 | K15: =J15 -> 27630
A16: Total Assets | B16: 52148 | C16: 62131 | D16: 82338 | E16: 106618 | F16: 122070 | G16: =SUM(G7:G15) -> 127133.44 | H16: =SUM(H7:H15) -> 133754.01 | I16: =SUM(I7:I15) -> 144285.49 | J16: =SUM(J7:J15) -> 155834.94 | K16: =SUM(K7:K15) -> 168128.6
A18: Liabilities
A19: A/P & Accrued Liabilities | B19: 10658 | C19: 16669 | D19: 23460 | E19: 23511 | F19: 23197 | G19: =G109 -> 23394.313 | H19: =H109 -> 24096.142 | I19: =I109 -> 24819.026 | J19: =J109 -> 25563.597 | K19: =K109 -> 26330.505
A20: Deferred Revenue | B20: 1458 | C20: 1447 | D20: 1747 | E20: 2864 | F20: 3168 | G20: =G110 -> 3018.621 | H20: =H110 -> 3109.1796 | I20: =I110 -> 3202.455 | J20: =J110 -> 3298.5287 | K20: =K110 -> 3397.4845
A21: NEW Revolver | G21: =-IF(G92<0,G92,0) -> 0 | H21: =-IF(H92<0,H92,0) -> 0 | I21: =-IF(I92<0,I92,0) -> 0 | J21: =-IF(J92<0,J92,0) -> 0 | K21: =-IF(K92<0,K92,0) -> 0
A22: Debt | B22: 11739 | C22: 6834 | D22: 3099 | E22: 5230 | F22: 8213 | G22: =G113 -> 5860 | H22: =H113 -> 1744 | I22: =I113 -> 1045 | J22: =J113 -> 802 | K22: =K113 -> 707
A23: Other Liabilities | B23: 4614 | C23: 5598 | D23: 8134 | E23: 11404 | F23: 13812 | G23: =G111 -> 12225.415 | H23: =H111 -> 12592.178 | I23: =I111 -> 12969.943 | J23: =J111 -> 13359.041 | K23: =K111 -> 13759.812
A24: Total Liabilities | B24: =SUM(B19:B23) -> 28469 | C24: =SUM(C19:C23) -> 30548 | D24: =SUM(D19:D23) -> 36440 | E24: =SUM(E19:E23) -> 43009 | F24: =SUM(F19:F23) -> 48390 | G24: =SUM(G19:G23) -> 44498.349 | H24: =SUM(H19:H23) -> 41541.499 | I24: =SUM(I19:I23) -> 42036.424 | ... K24: =SUM(K19:K23) -> 44194.802
A25: Shareholder's Equity
A26: Paid-in Capital | B26: 27261 | C26: 29804 | D26: 32180 | E26: 34895 | F26: 38374 | G26: =F26 -> 38374 | H26: =G26 -> 38374 | I26: =H26 -> 38374 | J26: =I26 -> 38374 | K26: =J26 -> 38374
A27: Other Equity | B27: 363 | C27: 54 | D27: -361 | E27: -143 | F27: -670 | G27: =F27 -> -670 | H27: =G27 -> -670 | I27: =H27 -> -670 | J27: =I27 -> -670 | K27: =J27 -> -670
A28: Retained Earnings | B28: -5399 | C28: 331 | D28: 12885 | E28: 27882 | F28: 35209 | G28: =G59 -> 44164.093 | H28: =H59 -> 53741.515 | I28: =I59 -> 63778.062 | J28: =J59 -> 74340.777 | K28: =K59 -> 85462.8
A29: Noncontrolling Interests | B29: 1454 | C29: 1394 | D29: 1194 | E29: 975 | F29: 767 | G29: =F29 -> 767 | H29: =G29 -> 767 | I29: =H29 -> 767 | J29: =I29 -> 767 | K29: =J29 -> 767
A30: Shareholder's Equity | B30: =SUM(B26:B29) -> 23679 | C30: =SUM(C26:C29) -> 31583 | D30: =SUM(D26:D29) -> 45898 | E30: =SUM(E26:E29) -> 63609 | F30: =SUM(F26:F29) -> 73680 | G30: =SUM(G26:G29) -> 82635.093 | H30: =SUM(H26:H29) -> 92212.515 | I30: =SUM(I26:I29) -> 102249.06 | ... K30: =SUM(K26:K29) -> 123933.8
A31: Total Liabilities and Shareholder's Equity | B31: =B24+B30 -> 52148 | C31: =C24+C30 -> 62131 | D31: =D24+D30 -> 82338 | E31: =E24+E30 -> 106618 | F31: =F24+F30 -> 122070 | G31: =G24+G30 -> 127133.44 | H31: =H24+H30 -> 133754.01 | I31: =I24+I30 -> 144285.49 | ... K31: =K24+K30 -> 168128.6
A32: Check | B32: 0 | C32: 0 | D32: 0 | E32: 0 | F32: 0 | G32: =G16-G31 -> 0 | H32: =H16-H31 -> 0 | I32: =I16-I31 -> 0 | J32: =J16-J31 -> 0 | K32: =K16-K31 -> 0 | L32: =SUM(B32:K32) -> 0
A34: Beginning PP&E | G34: =F37 -> 35836 | H34: =G37 -> 40363.931 | I34: =H37 -> 45027.701 | J34: =I37 -> 49831.383 | K34: =J37 -> 54779.176
A35: + Capex | G35: =+G114 -> 10062.07 | H35: =+H114 -> 10363.932 | I35: =+I114 -> 10674.85 | J35: =+J114 -> 10995.096 | K35: =+K114 -> 11324.948
A36: - D&A | G36: =G97 -> 5534.1385 | H36: =H97 -> 5700.1627 | I36: =I97 -> 5871.1675 | J36: =J97 -> 6047.3026 | K36: =K97 -> 6228.7216
A37: Ending PP&E | F37: =F13 -> 35836 | G37: =G34+G35-G36 -> 40363.931 | H37: =H34+H35-H36 -> 45027.701 | I37: =I34+I35-I36 -> 49831.383 | J37: =J34+J35-J36 -> 54779.176 | K37: =K34+K35-K36 -> 59875.403
A39: INCOME STATEMENT
A40: Revenues | B40: 31536 | C40: 53823 | D40: 81462 | E40: 96773 | F40: 97690 | G40: =G95 -> 100620.7 | H40: =H95 -> 103639.32 | I40: =I95 -> 106748.5 | J40: =J95 -> 109950.96 | K40: =K95 -> 113249.48
A41: Cost of Goods Sold | B41: 22584 | C41: 37306 | D41: 56862 | E41: 74446 | F41: 74872 | G41: =G96 -> 75465.525 | H41: =H96 -> 77729.491 | I41: =I96 -> 80061.375 | J41: =J96 -> 82463.217 | K41: =K96 -> 84937.113
A42: Gross profit | B42: 8952 | C42: 16517 | D42: 24600 | E42: 22327 | F42: 22818 | G42: =G40-G41 -> 25155.175 | H42: =H40-H41 -> 25909.83 | I42: =I40-I41 -> 26687.125 | J42: =J40-J41 -> 27487.739 | K42: =K40-K41 -> 28312.371
A43: R&D | B43: 1491 | C43: 2593 | D43: 3075 | E43: 3969 | F43: 4540 | G43: =G98 -> 4527.9315 | H43: =H98 -> 4663.7694 | I43: =I98 -> 4803.6825 | J43: =J98 -> 4947.793 | K43: =K98 -> 5096.2268
...
